Workbook

Sheet Site Power Dimensioning
A1: Telecom Site Power Dimensioning Model (-48V DC System)
A2: Scenario 1: VRLA battery site, 60 A load, 6 h backup. Change the yellow cells to size any site.
A3: INPUTS | B3: Value | C3: Unit / Note | F3: Standard cable sizes (mm2)
A4: DC load current | B4: 60 | C4: A | F4: 16
A5: Nominal voltage | B5: 48 | C5: V | F5: 25
A6: Backup time | B6: 6 | C6: hours | F6: 35
A7: Depth of Discharge (DoD) | B7: 0.8 | C7: VRLA typical 0.8; lithium 0.9 | F7: 50
A8: Ageing factor | B8: 1.25 | C8: battery ageing margin | F8: 70
A9: Temperature factor | B9: 1 | C9: 1.0 normal; 1.1 for hot sites | F9: 95
A10: Charging current factor | B10: 0.1 | C10: 0.1 = 0.1C | F10: 120
A11: Rectifier module rating | B11: 50 | C11: A per module | F11: Source: typical standard sizes; confirm with ampacity tables / customer spec.
A12: Rectifier efficiency | B12: 0.96 | C12: 0.96 = 96%
A13: AC voltage (single phase) | B13: 230 | C13: V | F13: LEGEND
A14: AC power factor | B14: 0.99 | C14: rectifier input PF | F14: Yellow cells, blue text = inputs (edit these)
A15: Extra AC load (AC, lights) | B15: 3 | C15: kW | F15: Green cells = final design results
A16: DG margin | B16: 0.2 | C16: 0.2 = 20% growth margin | F16: Other cells = formulas (do not edit)
A17: DG power factor | B17: 0.8 | C17: typical 0.8
A18: Cable length (one way) | B18: 10 | C18: m
A19: Allowed voltage drop | B19: 1 | C19: V (about 2% of 48V)
A20: Copper resistivity | B20: 0.0175 | C20: ohm-mm2/m
A22: CALCULATIONS | B22: Result | C22: Meaning
A23: DC load power (kW) | B23: =B4*B5/1000 -> 2.88 | C23: P = V x I
A24: Basic battery capacity (Ah) | B24: =B4*B6 -> 360 | C24: Load x hours
A25: Required battery (Ah) | B25: =B4*B6/B7*B8*B9 -> 562.5 | C25: Corrected for DoD, ageing, temperature
A26: Standard battery size (Ah) | B26: =CEILING(B25,100) -> 600 | C26: Next standard size (100 Ah steps)
A27: Battery charging current (A) | B27: =B10*B26 -> 60 | C27: Charging factor x battery Ah
A28: Total rectifier current (A) | B28: =B4+B27 -> 120 | C28: Load + battery charging
A29: Modules needed | B29: =ROUNDUP(B28/B11,0) -> 3 | C29: Rounded up to whole modules
A30: Modules with N+1 | B30: =B29+1 -> 4 | C30: One extra module for redundancy
A31: Installed rectifier capacity (A) | B31: =B30*B11 -> 200 | C31: Total rectifier capacity
A32: DC output power (kW) | B32: =B28*B5/1000 -> 5.76 | C32: Rectifier output at full load + charging
A33: AC input power (kW) | B33: =B32/B12 -> 6 | C33: After rectifier efficiency
A34: AC input current (A) | B34: =B33*1000/(B13*B14) -> 26.350461 | C34: I = P / (V x PF)
A35: AC breaker size (A) | B35: =CEILING(1.25*B34,10) -> 40 | C35: 1.25 x current, rounded to 10 A steps
A36: Total AC load (kW) | B36: =B33+B15 -> 9 | C36: Rectifier input + extra AC load
A37: Load with margin (kW) | B37: =B36*(1+B16) -> 10.8 | C37: Growth margin added
A38: DG required (kVA) | B38: =B37/B17 -> 13.5 | C38: kVA = kW / PF
A39: Standard DG size (kVA) | B39: =CEILING(B38,5) -> 15 | C39: Next standard size (5 kVA steps)
A40: DC cable area required (mm2) | B40: =B20*2*B18*B28/B19 -> 42 | C40: Area = rho x 2L x I / Vdrop
A41: Standard cable size (mm2) | B41: =INDEX(F4:F10,COUNTIF(F4:F10,"<"&B40)+1) -> 50 | C41: Next size from table (check ampacity separately)
...

Sheet Scenario 2 Lithium
A1: Scenario 2: Lithium Battery Site (Hot Location)
A2: Scenario 2: Lithium battery (DoD 0.9), 40 A load, 4 h backup, temperature factor 1.1.
A3: INPUTS | B3: Value | C3: Unit / Note | F3: Standard cable sizes (mm2)
A4: DC load current | B4: 40 | C4: A | F4: 16
A5: Nominal voltage | B5: 48 | C5: V | F5: 25
A6: Backup time | B6: 4 | C6: hours | F6: 35
A7: Depth of Discharge (DoD) | B7: 0.9 | C7: VRLA typical 0.8; lithium 0.9 | F7: 50
A8: Ageing factor | B8: 1.1 | C8: battery ageing margin | F8: 70
A9: Temperature factor | B9: 1.1 | C9: 1.0 normal; 1.1 for hot sites | F9: 95
A10: Charging current factor | B10: 0.1 | C10: 0.1 = 0.1C | F10: 120
A11: Rectifier module rating | B11: 50 | C11: A per module | F11: Source: typical standard sizes; confirm with ampacity tables / customer spec.
A12: Rectifier efficiency | B12: 0.96 | C12: 0.96 = 96%
A13: AC voltage (single phase) | B13: 230 | C13: V | F13: LEGEND
A14: AC power factor | B14: 0.99 | C14: rectifier input PF | F14: Yellow cells, blue text = inputs (edit these)
A15: Extra AC load (AC, lights) | B15: 3 | C15: kW | F15: Green cells = final design results
A16: DG margin | B16: 0.2 | C16: 0.2 = 20% growth margin | F16: Other cells = formulas (do not edit)
A17: DG power factor | B17: 0.8 | C17: typical 0.8
A18: Cable length (one way) | B18: 10 | C18: m
A19: Allowed voltage drop | B19: 1 | C19: V (about 2% of 48V)
A20: Copper resistivity | B20: 0.0175 | C20: ohm-mm2/m
A22: CALCULATIONS | B22: Result | C22: Meaning
A23: DC load power (kW) | B23: =B4*B5/1000 -> 1.92 | C23: P = V x I
A24: Basic battery capacity (Ah) | B24: =B4*B6 -> 160 | C24: Load x hours
A25: Required battery (Ah) | B25: =B4*B6/B7*B8*B9 -> 215.11111 | C25: Corrected for DoD, ageing, temperature
A26: Standard battery size (Ah) | B26: =CEILING(B25,100) -> 300 | C26: Next standard size (100 Ah steps)
A27: Battery charging current (A) | B27: =B10*B26 -> 30 | C27: Charging factor x battery Ah
A28: Total rectifier current (A) | B28: =B4+B27 -> 70 | C28: Load + battery charging
A29: Modules needed | B29: =ROUNDUP(B28/B11,0) -> 2 | C29: Rounded up to whole modules
A30: Modules with N+1 | B30: =B29+1 -> 3 | C30: One extra module for redundancy
A31: Installed rectifier capacity (A) | B31: =B30*B11 -> 150 | C31: Total rectifier capacity
A32: DC output power (kW) | B32: =B28*B5/1000 -> 3.36 | C32: Rectifier output at full load + charging
A33: AC input power (kW) | B33: =B32/B12 -> 3.5 | C33: After rectifier efficiency
A34: AC input current (A) | B34: =B33*1000/(B13*B14) -> 15.371102 | C34: I = P / (V x PF)
A35: AC breaker size (A) | B35: =CEILING(1.25*B34,10) -> 20 | C35: 1.25 x current, rounded to 10 A steps
A36: Total AC load (kW) | B36: =B33+B15 -> 6.5 | C36: Rectifier input + extra AC load
A37: Load with margin (kW) | B37: =B36*(1+B16) -> 7.8 | C37: Growth margin added
A38: DG required (kVA) | B38: =B37/B17 -> 9.75 | C38: kVA = kW / PF
A39: Standard DG size (kVA) | B39: =CEILING(B38,5) -> 10 | C39: Next standard size (5 kVA steps)
A40: DC cable area required (mm2) | B40: =B20*2*B18*B28/B19 -> 24.5 | C40: Area = rho x 2L x I / Vdrop
A41: Standard cable size (mm2) | B41: =INDEX(F4:F10,COUNTIF(F4:F10,"<"&B40)+1) -> 25 | C41: Next size from table (check ampacity separately)
...

Sheet Charts
A1: Visualization of Power Dimensioning Results
A2: All chart data below is linked by formula to the model sheets, so charts update when you change the yellow input cells.
A4: Chart 1: Scenario 1 vs Scenario 2 (key design sizes)
A5: Item | B5: Scenario 1 (VRLA) | C5: Scenario 2 (Lithium)
A6: Battery (Ah) | B6: ='Site Power Dimensioning'!B26 -> 600 | C6: ='Scenario 2 Lithium'!B26 -> 300
A7: Installed rectifier (A) | B7: ='Site Power Dimensioning'!B31 -> 200 | C7: ='Scenario 2 Lithium'!B31 -> 150
A8: AC breaker (A) | B8: ='Site Power Dimensioning'!B35 -> 40 | C8: ='Scenario 2 Lithium'!B35 -> 20
A9: DG set (kVA) | B9: ='Site Power Dimensioning'!B39 -> 15 | C9: ='Scenario 2 Lithium'!B39 -> 10
A10: DC cable (mm2) | B10: ='Site Power Dimensioning'!B41 -> 50 | C10: ='Scenario 2 Lithium'!B41 -> 25
A22: Chart 2: Required battery capacity vs backup time
A23: Backup time (h) | B23: Scenario 1 required Ah | C23: Scenario 2 required Ah
A24: 1 | B24: ='Site Power Dimensioning'!$B$4*A24/'Site Power Dimensioning'!$B$7*'Site Power Dimensioning'!$B$8*'Site Power Dimensioning'!$B$9 -> 93.75 | C24: ='Scenario 2 Lithium'!$B$4*A24/'Scenario 2 Lithium'!$B$7*'Scenario 2 Lithium'!$B$8*'Scenario 2 Lithium'!$B$9 -> 53.777778
A25: 2 | B25: ='Site Power Dimensioning'!$B$4*A25/'Site Power Dimensioning'!$B$7*'Site Power Dimensioning'!$B$8*'Site Power Dimensioning'!$B$9 -> 187.5 | C25: ='Scenario 2 Lithium'!$B$4*A25/'Scenario 2 Lithium'!$B$7*'Scenario 2 Lithium'!$B$8*'Scenario 2 Lithium'!$B$9 -> 107.55556
A26: 3 | B26: ='Site Power Dimensioning'!$B$4*A26/'Site Power Dimensioning'!$B$7*'Site Power Dimensioning'!$B$8*'Site Power Dimensioning'!$B$9 -> 281.25 | C26: ='Scenario 2 Lithium'!$B$4*A26/'Scenario 2 Lithium'!$B$7*'Scenario 2 Lithium'!$B$8*'Scenario 2 Lithium'!$B$9 -> 161.33333
A27: 4 | B27: ='Site Power Dimensioning'!$B$4*A27/'Site Power Dimensioning'!$B$7*'Site Power Dimensioning'!$B$8*'Site Power Dimensioning'!$B$9 -> 375 | C27: ='Scenario 2 Lithium'!$B$4*A27/'Scenario 2 Lithium'!$B$7*'Scenario 2 Lithium'!$B$8*'Scenario 2 Lithium'!$B$9 -> 215.11111
A28: 5 | B28: ='Site Power Dimensioning'!$B$4*A28/'Site Power Dimensioning'!$B$7*'Site Power Dimensioning'!$B$8*'Site Power Dimensioning'!$B$9 -> 468.75 | C28: ='Scenario 2 Lithium'!$B$4*A28/'Scenario 2 Lithium'!$B$7*'Scenario 2 Lithium'!$B$8*'Scenario 2 Lithium'!$B$9 -> 268.88889
A29: 6 | B29: ='Site Power Dimensioning'!$B$4*A29/'Site Power Dimensioning'!$B$7*'Site Power Dimensioning'!$B$8*'Site Power Dimensioning'!$B$9 -> 562.5 | C29: ='Scenario 2 Lithium'!$B$4*A29/'Scenario 2 Lithium'!$B$7*'Scenario 2 Lithium'!$B$8*'Scenario 2 Lithium'!$B$9 -> 322.66667
A30: 7 | B30: ='Site Power Dimensioning'!$B$4*A30/'Site Power Dimensioning'!$B$7*'Site Power Dimensioning'!$B$8*'Site Power Dimensioning'!$B$9 -> 656.25 | C30: ='Scenario 2 Lithium'!$B$4*A30/'Scenario 2 Lithium'!$B$7*'Scenario 2 Lithium'!$B$8*'Scenario 2 Lithium'!$B$9 -> 376.44444
A31: 8 | B31: ='Site Power Dimensioning'!$B$4*A31/'Site Power Dimensioning'!$B$7*'Site Power Dimensioning'!$B$8*'Site Power Dimensioning'!$B$9 -> 750 | C31: ='Scenario 2 Lithium'!$B$4*A31/'Scenario 2 Lithium'!$B$7*'Scenario 2 Lithium'!$B$8*'Scenario 2 Lithium'!$B$9 -> 430.22222
A32: 9 | B32: ='Site Power Dimensioning'!$B$4*A32/'Site Power Dimensioning'!$B$7*'Site Power Dimensioning'!$B$8*'Site Power Dimensioning'!$B$9 -> 843.75 | C32: ='Scenario 2 Lithium'!$B$4*A32/'Scenario 2 Lithium'!$B$7*'Scenario 2 Lithium'!$B$8*'Scenario 2 Lithium'!$B$9 -> 484
A33: 10 | B33: ='Site Power Dimensioning'!$B$4*A33/'Site Power Dimensioning'!$B$7*'Site Power Dimensioning'!$B$8*'Site Power Dimensioning'!$B$9 -> 937.5 | C33: ='Scenario 2 Lithium'!$B$4*A33/'Scenario 2 Lithium'!$B$7*'Scenario 2 Lithium'!$B$8*'Scenario 2 Lithium'!$B$9 -> 537.77778
A34: 11 | B34: ='Site Power Dimensioning'!$B$4*A34/'Site Power Dimensioning'!$B$7*'Site Power Dimensioning'!$B$8*'Site Power Dimensioning'!$B$9 -> 1031.25 | C34: ='Scenario 2 Lithium'!$B$4*A34/'Scenario 2 Lithium'!$B$7*'Scenario 2 Lithium'!$B$8*'Scenario 2 Lithium'!$B$9 -> 591.55556
A35: 12 | B35: ='Site Power Dimensioning'!$B$4*A35/'Site Power Dimensioning'!$B$7*'Site Power Dimensioning'!$B$8*'Site Power Dimensioning'!$B$9 -> 1125 | C35: ='Scenario 2 Lithium'!$B$4*A35/'Scenario 2 Lithium'!$B$7*'Scenario 2 Lithium'!$B$8*'Scenario 2 Lithium'!$B$9 -> 645.33333
A40: Chart 3: Rectifier requirement vs DC load (Scenario 1 settings)
A41: DC load (A) | B41: Battery std (Ah) | C41: Total rectifier current (A) | D41: Installed capacity N+1 (A)
A42: 20 | B42: =CEILING(A42*'Site Power Dimensioning'!$B$6/'Site Power Dimensioning'!$B$7*'Site Power Dimensioning'!$B$8*'Site Power Dimensioning'!$B$9,100) -> 200 | C42: =A42+'Site Power Dimensioning'!$B$10*B42 -> 40 | D42: =(ROUNDUP(C42/'Site Power Dimensioning'!$B$11,0)+1)*'Site Power Dimensioning'!$B$11 -> 100
A43: 30 | B43: =CEILING(A43*'Site Power Dimensioning'!$B$6/'Site Power Dimensioning'!$B$7*'Site Power Dimensioning'!$B$8*'Site Power Dimensioning'!$B$9,100) -> 300 | C43: =A43+'Site Power Dimensioning'!$B$10*B43 -> 60 | D43: =(ROUNDUP(C43/'Site Power Dimensioning'!$B$11,0)+1)*'Site Power Dimensioning'!$B$11 -> 150
A44: 40 | B44: =CEILING(A44*'Site Power Dimensioning'!$B$6/'Site Power Dimensioning'!$B$7*'Site Power Dimensioning'!$B$8*'Site Power Dimensioning'!$B$9,100) -> 400 | C44: =A44+'Site Power Dimensioning'!$B$10*B44 -> 80 | D44: =(ROUNDUP(C44/'Site Power Dimensioning'!$B$11,0)+1)*'Site Power Dimensioning'!$B$11 -> 150
A45: 50 | B45: =CEILING(A45*'Site Power Dimensioning'!$B$6/'Site Power Dimensioning'!$B$7*'Site Power Dimensioning'!$B$8*'Site Power Dimensioning'!$B$9,100) -> 500 | C45: =A45+'Site Power Dimensioning'!$B$10*B45 -> 100 | D45: =(ROUNDUP(C45/'Site Power Dimensioning'!$B$11,0)+1)*'Site Power Dimensioning'!$B$11 -> 150
A46: 60 | B46: =CEILING(A46*'Site Power Dimensioning'!$B$6/'Site Power Dimensioning'!$B$7*'Site Power Dimensioning'!$B$8*'Site Power Dimensioning'!$B$9,100) -> 600 | C46: =A46+'Site Power Dimensioning'!$B$10*B46 -> 120 | D46: =(ROUNDUP(C46/'Site Power Dimensioning'!$B$11,0)+1)*'Site Power Dimensioning'!$B$11 -> 200
A47: 70 | B47: =CEILING(A47*'Site Power Dimensioning'!$B$6/'Site Power Dimensioning'!$B$7*'Site Power Dimensioning'!$B$8*'Site Power Dimensioning'!$B$9,100) -> 700 | C47: =A47+'Site Power Dimensioning'!$B$10*B47 -> 140 | D47: =(ROUNDUP(C47/'Site Power Dimensioning'!$B$11,0)+1)*'Site Power Dimensioning'!$B$11 -> 200
A48: 80 | B48: =CEILING(A48*'Site Power Dimensioning'!$B$6/'Site Power Dimensioning'!$B$7*'Site Power Dimensioning'!$B$8*'Site Power Dimensioning'!$B$9,100) -> 800 | C48: =A48+'Site Power Dimensioning'!$B$10*B48 -> 160 | D48: =(ROUNDUP(C48/'Site Power Dimensioning'!$B$11,0)+1)*'Site Power Dimensioning'!$B$11 -> 250
A49: 90 | B49: =CEILING(A49*'Site Power Dimensioning'!$B$6/'Site Power Dimensioning'!$B$7*'Site Power Dimensioning'!$B$8*'Site Power Dimensioning'!$B$9,100) -> 900 | C49: =A49+'Site Power Dimensioning'!$B$10*B49 -> 180 | D49: =(ROUNDUP(C49/'Site Power Dimensioning'!$B$11,0)+1)*'Site Power Dimensioning'!$B$11 -> 250
A50: 100 | B50: =CEILING(A50*'Site Power Dimensioning'!$B$6/'Site Power Dimensioning'!$B$7*'Site Power Dimensioning'!$B$8*'Site Power Dimensioning'!$B$9,100) -> 1000 | C50: =A50+'Site Power Dimensioning'!$B$10*B50 -> 200 | D50: =(ROUNDUP(C50/'Site Power Dimensioning'!$B$11,0)+1)*'Site Power Dimensioning'!$B$11 -> 250
A58: Chart 4: DG set load breakdown (Scenario 1)
A59: Component | B59: kW
A60: Rectifier AC input | B60: ='Site Power Dimensioning'!B33 -> 6
A61: Extra AC load (AC, lights) | B61: ='Site Power Dimensioning'!B15 -> 3
A62: Growth margin | B62: ='Site Power Dimensioning'!B37-'Site Power Dimensioning'!B36 -> 1.8
A66: Chart 5: Rectifier DC output split (Scenario 1)
...

Sheet Notes
A1: NOTES AND ASSUMPTIONS
A2: Purpose | B2: Excel model to size battery, rectifier, AC breaker, DG set and DC cable for a telecom site.
A3: Important | B3: All input values are typical/illustrative. Real projects follow customer specifications and vendor datasheets.
A5: FORMULAS USED
A6: DC power | B6: P = V x I
A7: Battery capacity (Ah) | B7: Load current x backup hours / DoD x ageing factor x temperature factor, then next standard size
A8: Rectifier current | B8: Load current + battery charging current (charging factor x battery Ah)
A9: Rectifier modules | B9: ROUNDUP(total current / module rating), plus 1 module for N+1 redundancy
A10: AC input power | B10: DC output power / rectifier efficiency
A11: AC input current | B11: I = P / (V x PF), single phase
A12: AC breaker | B12: 1.25 x AC input current, rounded up to 10 A steps
A13: DG kVA | B13: (Rectifier AC input + extra AC load) x (1 + margin) / DG power factor, rounded to 5 kVA steps
A14: DC cable area | B14: Area = resistivity x 2 x length x current / allowed voltage drop
A16: REFERENCES
A17: Battery sizing standard | B17: IEEE 485 (lead-acid battery sizing). Confirm method with customer standard.
A18: Cable | B18: Standard size from table only checks voltage drop. Also check cable ampacity from standard tables.
A19: Charging factor | B19: 0.1C is a typical VRLA assumption; lithium batteries may allow higher rates (check datasheet).
A20: Resistivity | B20: Copper 0.0175 ohm-mm2/m (typical value at about 20 C).
A22: HOW TO USE | B22: Edit only yellow input cells (blue text). Results update automatically. Use the Scenario 2 sheet as a second example.
